<?xml version="1.0"?>

<robot name="head" xmlns:xacro="http://ros.org/wiki/xacro">
    <xacro:macro name="head" params="parent">
        <link name="head_link">

            <inertial>
                <mass value="0.18" />
                <inertia ixx="0.0002835" ixy="0.0" ixz="0.0" iyy="0.0002835" iyz="0.0" izz="0.000324" />
            </inertial>

            <collision>
                <geometry>
                    <cylinder radius="0.05" length="0.24" />
                </geometry>
            </collision>

            <visual>
            <geometry>
                <cylinder radius="0.05" length="0.24" />
            </geometry>
            </visual>

        </link>

        <joint name="head_joint" type="continuous">
            <origin xyz="0 0 1.0" rpy="0 0 0"/>
            <axis xyz="1 0 0" />
            <parent link="${parent}" />
            <child link="head_link" />
        </joint>


        <!--                GAZEBO RELATED PART                             -->

        <!-- ROS Control plugin for Gazebo -->
        <gazebo>
            <plugin name="gazebo_ros_control" filename="libgazebo_ros_control.so" />
        </gazebo>

        <!-- transmission -->
        <transmission name="base_to_second_trans">
            <type>transmission_interface/SimpleTransmission</type>
            <actuator name="motor1">
            <mechanicalReduction>1</mechanicalReduction>
            </actuator>
            <joint name="head_joint">
                <hardwareInterface>hardware_interface/EffortJointInterface</hardwareInterface>
            </joint>
        </transmission>

    </xacro:macro>
        

</robot>