<?xml version="1.0" ?>
<!-- =================================================================================== -->
<!-- |    This document was autogenerated by xacro from pioneer3at.urdf.xacro          | -->
<!-- |    EDITING THIS FILE BY HAND IS NOT RECOMMENDED                                 | -->
<!-- =================================================================================== -->
<robot name="pioneer3at" xmlns:xacro="http://ros.org/wiki/xacro">

  <xacro:macro name="pioneer3at" params="prefix">

  <link name="base_footprint">
   </link>
  <joint name="base_footprint_joint" type="fixed">
     <parent link="base_footprint"/>
     <child link="base_link"/>
  </joint>
    <!-- Chassis -->
    <link name="base_link">
      <!--  For pointers on inertial and gazebo-related parameters see
            * http://wiki.ros.org/urdf/Tutorials/Adding%20Physical%20and%20Collision%20Properties%20to%20a%20URDF%20Model
                        * http://answers.gazebosim.org/question/4372/the-inertia-matrix-explained/
            * http://gazebosim.org/tutorials?tut=inertia&cat=build_robot, and 
                        * http://gazebosim.org/tutorials/?tut=ros_urdf
                        * http://en.wikipedia.org/wiki/List_of_moment_of_inertia_tensors  
                  -->
      <inertial>
        <mass value="21.5"/>
        <!-- P3AT 18.6kg plus three batteries @ 2.4kg each  minus four wheels @ 1.4 kg ea and top plate @ 0.1 kg-->
        <origin xyz=" -0.1 0 0.177"/>
        <inertia ixx="0.3338" ixy="0.0" ixz="0.0" iyy="0.4783" iyz="0.0" izz="0.3338"/>
      </inertial>
      <visual>
        <origin rpy="0 0 0" xyz="0 0 0.177"/>
        <geometry name="pioneer_geom">
          <mesh filename="package://follower_description/meshes/p3at/chassis.stl"/>
        </geometry>
        <material name="ChassisRed">
          <color rgba="0.851 0.0 0.0 1.0"/>
        </material>
      </visual>
      <collision>
        <origin rpy="0 0 0" xyz="0 0 0.177"/>
        <geometry>
          <mesh filename="package://follower_description/meshes/p3at/chassis.stl"/>
        </geometry>
      </collision>
    </link>
    <gazebo reference="base_link">
      <material value="Gazebo/Red"/>
    </gazebo>
    <!-- Top -->
    <link name="top_plate">
      <inertial>
        <mass value="0.1"/>
        <origin xyz="-0.025 0 -0.223"/>
        <inertia ixx="1.0" ixy="0.0" ixz="0.0" iyy="1.0" iyz="0.0" izz="1.0"/>
      </inertial>
      <visual>
        <origin rpy="0 0 0" xyz="0 0 0"/>
        <geometry name="pioneer_geom">
          <mesh filename="package://follower_description/meshes/p3at/top.stl"/>
        </geometry>
        <material name="TopBlack">
          <color rgba="0.038 0.038 0.038 1.0"/>
        </material>
      </visual>
    </link>
    <gazebo reference="top_plate">
      <material>Gazebo/Black</material>
    </gazebo>
    <joint name="base_top_joint" type="fixed">
      <origin rpy="0 0 0" xyz="0.003 0 0.274"/>
      <parent link="base_link"/>
      <child link="top_plate"/>
    </joint>
    <!-- Front + Back Sonar -->
    <link name="front_sonar">
      <inertial>
        <mass value="0.1"/>
        <origin xyz="0 0 0"/>
        <inertia ixx="1.0" ixy="0.0" ixz="0.0" iyy="1.0" iyz="0.0" izz="1.0"/>
      </inertial>
      <visual>
        <origin rpy="0 0 0" xyz="0 0 0"/>
        <geometry name="pioneer_geom">
          <mesh filename="package://follower_description/meshes/p3at/front_sonar.stl"/>
        </geometry>
        <material name="SonarYellow">
          <color rgba="0.715 0.583 0.210 1.0"/>
        </material>
      </visual>
    </link>
    <gazebo reference="front_sonar">
      <material value="Gazebo/Yellow"/>
    </gazebo>
    <joint name="base_front_joint" type="fixed">
      <origin rpy="0 0 0" xyz="0.193 0 0.25"/>
      <parent link="base_link"/>
      <child link="front_sonar"/>
    </joint>
    <link name="back_sonar">
      <inertial>
        <mass value="0.1"/>
        <origin xyz="0 0 0"/>
        <inertia ixx="1.0" ixy="0.0" ixz="0.0" iyy="1.0" iyz="0.0" izz="1.0"/>
      </inertial>
      <visual>
        <origin rpy="0 0 0" xyz="0 0 0"/>
        <geometry name="pioneer_geom">
          <mesh filename="package://follower_description/meshes/p3at/back_sonar.stl"/>
        </geometry>
        <material name="SonarYellow">
          <color rgba="0.715 0.583 0.210 1.0"/>
        </material>
      </visual>
    </link>
    <gazebo reference="back_sonar">
      <material value="Gazebo/Yellow"/>
    </gazebo>
    <joint name="base_back_joint" type="fixed">
      <origin rpy="0 0 0" xyz="-0.187 0 0.247"/>
      <parent link="base_link"/>
      <child link="back_sonar"/>
    </joint>
    <!-- Front Axles + Wheels + Hubcaps -->
    <link name="p3at_front_left_axle">
      <inertial>
        <mass value="0.1"/>
        <origin xyz="0 0 0"/>
        <inertia ixx="1.0" ixy="0.0" ixz="0.0" iyy="1.0" iyz="0.0" izz="1.0"/>
      </inertial>
      <visual>
        <origin rpy="0 0 0" xyz="0 0 0"/>
        <geometry name="pioneer_geom">
          <mesh filename="package://follower_description/meshes/p3at/axle.stl"/>
        </geometry>
        <material name="AxleGrey">
          <color rgba="0.5 0.5 0.5 1"/>
        </material>
      </visual>
    </link>
    <gazebo reference="p3at_front_left_axle">
      <material value="Gazebo/Grey"/>
    </gazebo>
    <joint name="base_front_left_axle_joint" type="fixed">
      <origin rpy="0 0 0" xyz="0.135 0.156 0.111"/>
      <parent link="base_link"/>
      <child link="p3at_front_left_axle"/>
    </joint>
    <link name="p3at_front_left_hub">
      <inertial>
        <mass value="0.1"/>
        <origin xyz="0 0 0"/>
        <inertia ixx="1.0" ixy="0.0" ixz="0.0" iyy="1.0" iyz="0.0" izz="1.0"/>
      </inertial>
      <visual>
        <origin rpy="0 0 0" xyz="0 0 0"/>
        <geometry name="pioneer_geom">
          <mesh filename="package://follower_description/meshes/p3at/left_hubcap.stl"/>
        </geometry>
        <material name="HubcapYellow">
          <color rgba="1.0 0.811 0.151 1.0"/>
        </material>
      </visual>
    </link>
    <gazebo reference="p3at_front_left_hub">
      <material value="Gazebo/Yellow"/>
    </gazebo>
    <joint name="base_front_left_hub_joint" type="fixed">
      <origin rpy="0 0 0" xyz="0 0.041 0"/>
      <parent link="p3at_front_left_axle"/>
      <child link="p3at_front_left_hub"/>
    </joint>
    <link name="p3at_front_left_wheel">
      <inertial>
        <mass value="1.2"/>
        <!-- 1.4 kg - axle 0.1 kg - hub 0.1 kg -->
        <origin xyz="0 0 0"/>
        <inertia ixx="0.012411765597" ixy="0" ixz="0" iyy="0.015218160428" iyz="0" izz="0.011763977943"/>
      </inertial>
      <visual>
        <origin rpy="0 0 0" xyz="0 0 0"/>
        <geometry name="pioneer_geom">
          <mesh filename="package://follower_description/meshes/p3at/wheel.stl"/>
        </geometry>
        <material name="WheelBlack">
          <color rgba="0.117 0.117 0.117 1"/>
        </material>
      </visual>
      <collision>
        <origin rpy="-1.57079635 0 0" xyz="0 0 0"/>
        <geometry>
          <!--mesh filename="package://follower_description/meshes/p3at/wheel.stl"/-->
          <cylinder length="0.075" radius="0.111"/>
        </geometry>
      </collision>
    </link>
    <gazebo reference="p3at_front_left_wheel">
      <material value="Gazebo/Black"/>
    </gazebo>
    <joint name="p3at_front_left_wheel_joint" type="continuous">
      <axis xyz="0 1 0"/>
      <anchor xyz="0 0 0"/>
      <limit effort="100" velocity="100"/>
      <joint_properties damping="0.7"/>
      <origin rpy="0 0 0" xyz="0 0 0"/>
      <parent link="p3at_front_left_hub"/>
      <child link="p3at_front_left_wheel"/>
    </joint>
    <!-- Back Axles + Wheels + Hubcaps -->
    <link name="p3at_back_left_axle">
      <inertial>
        <mass value="0.1"/>
        <origin xyz="0 0 0"/>
        <inertia ixx="1.0" ixy="0.0" ixz="0.0" iyy="1.0" iyz="0.0" izz="1.0"/>
      </inertial>
      <visual>
        <origin rpy="0 0 0" xyz="0 0 0"/>
        <geometry name="pioneer_geom">
          <mesh filename="package://follower_description/meshes/p3at/axle.stl"/>
        </geometry>
        <material name="AxleGrey">
          <color rgba="0.5 0.5 0.5 1"/>
        </material>
      </visual>
      <collision>
        <origin rpy="0 0 0" xyz="0 0 0"/>
        <geometry>
          <mesh filename="package://follower_description/meshes/p3at/axle.stl"/>
        </geometry>
      </collision>
    </link>
    <gazebo reference="p3at_back_left_axle">
      <material value="Gazebo/Grey"/>
    </gazebo>
    <joint name="p3at_back_left_axle_joint" type="fixed">
      <origin rpy="0 0 0" xyz="-0.134 0.156 0.111"/>
      <parent link="base_link"/>
      <child link="p3at_back_left_axle"/>
    </joint>
    <link name="p3at_back_left_hub">
      <inertial>
        <mass value="0.1"/>
        <origin xyz="0 0 0"/>
        <inertia ixx="1.0" ixy="0.0" ixz="0.0" iyy="1.0" iyz="0.0" izz="1.0"/>
      </inertial>
      <visual>
        <origin rpy="0 0 0" xyz="0 0 0"/>
        <geometry name="pioneer_geom">
          <mesh filename="package://follower_description/meshes/p3at/left_hubcap.stl"/>
        </geometry>
        <material name="HubcapYellow"/>
      </visual>
      <collision>
        <origin rpy="0 0 0" xyz="0 0 0"/>
        <geometry>
          <mesh filename="package://follower_description/meshes/p3at/left_hubcap.stl"/>
        </geometry>
      </collision>
    </link>
    <gazebo reference="p3at_back_left_hub">
      <material value="Gazebo/Yellow"/>
    </gazebo>
    <joint name="p3at_back_left_hub_joint" type="fixed">
      <origin rpy="0 0 0" xyz="-0 0.041 0"/>
      <parent link="p3at_back_left_axle"/>
      <child link="p3at_back_left_hub"/>
    </joint>
    <link name="p3at_back_left_wheel">
      <inertial>
        <mass value="1.2"/>
        <origin xyz="0 0 0"/>
        <inertia ixx="0.012411765597" ixy="0" ixz="0" iyy="0.015218160428" iyz="0" izz="0.011763977943"/>
      </inertial>
      <visual>
        <origin rpy="0 0 0" xyz="0 0 0"/>
        <geometry name="pioneer_geom">
          <mesh filename="package://follower_description/meshes/p3at/wheel.stl"/>
        </geometry>
        <material name="WheelBlack"/>
      </visual>
      <collision>
        <origin rpy="-1.57079635 0 0" xyz="0 0 0"/>
        <geometry>
          <!--mesh filename="package://follower_description/meshes/p3at/wheel.stl"/-->
          <cylinder length="0.075" radius="0.111"/>
        </geometry>
      </collision>
    </link>
    <gazebo reference="p3at_back_left_wheel">
      <material value="Gazebo/Black"/>
    </gazebo>
    <joint name="p3at_back_left_wheel_joint" type="continuous">
      <axis xyz="0 1 0"/>
      <anchor xyz="0 0 0"/>
      <limit effort="100" velocity="100"/>
      <joint_properties damping="0.7"/>
      <origin rpy="0 0 0" xyz="0 0 0"/>
      <parent link="p3at_back_left_hub"/>
      <child link="p3at_back_left_wheel"/>
    </joint>

    <!-- Front Axles + Wheels + Hubcaps -->
    <link name="p3at_front_right_axle">
      <inertial>
        <mass value="0.1"/>
        <origin xyz="0 0 0"/>
        <inertia ixx="1.0" ixy="0.0" ixz="0.0" iyy="1.0" iyz="0.0" izz="1.0"/>
      </inertial>
      <visual>
        <origin rpy="0 0 0" xyz="0 0 0"/>
        <geometry name="pioneer_geom">
          <mesh filename="package://follower_description/meshes/p3at/axle.stl"/>
        </geometry>
        <material name="AxleGrey">
          <color rgba="0.5 0.5 0.5 1"/>
        </material>
      </visual>
    </link>
    <gazebo reference="p3at_front_right_axle">
      <material value="Gazebo/Grey"/>
    </gazebo>
    <joint name="base_front_right_axle_joint" type="fixed">
      <origin rpy="0 0 0" xyz="0.135 -0.156 0.111"/>
      <parent link="base_link"/>
      <child link="p3at_front_right_axle"/>
    </joint>
    <link name="p3at_front_right_hub">
      <inertial>
        <mass value="0.1"/>
        <origin xyz="0 0 0"/>
        <inertia ixx="1.0" ixy="0.0" ixz="0.0" iyy="1.0" iyz="0.0" izz="1.0"/>
      </inertial>
      <visual>
        <origin rpy="0 0 0" xyz="0 0 0"/>
        <geometry name="pioneer_geom">
          <mesh filename="package://follower_description/meshes/p3at/right_hubcap.stl"/>
        </geometry>
        <material name="HubcapYellow">
          <color rgba="1.0 0.811 0.151 1.0"/>
        </material>
      </visual>
    </link>
    <gazebo reference="p3at_front_right_hub">
      <material value="Gazebo/Yellow"/>
    </gazebo>
    <joint name="base_front_right_hub_joint" type="fixed">
      <origin rpy="0 0 0" xyz="0 -0.041 0"/>
      <parent link="p3at_front_right_axle"/>
      <child link="p3at_front_right_hub"/>
    </joint>
    <link name="p3at_front_right_wheel">
      <inertial>
        <mass value="1.2"/>
        <!-- 1.4 kg - axle 0.1 kg - hub 0.1 kg -->
        <origin xyz="0 0 0"/>
        <inertia ixx="0.012411765597" ixy="0" ixz="0" iyy="0.015218160428" iyz="0" izz="0.011763977943"/>
      </inertial>
      <visual>
        <origin rpy="0 0 0" xyz="0 0 0"/>
        <geometry name="pioneer_geom">
          <mesh filename="package://follower_description/meshes/p3at/wheel.stl"/>
        </geometry>
        <material name="WheelBlack">
          <color rgba="0.117 0.117 0.117 1"/>
        </material>
      </visual>
      <collision>
        <origin rpy="-1.57079635 0 0" xyz="0 0 0"/>
        <geometry>
          <!--mesh filename="package://follower_description/meshes/p3at/wheel.stl"/-->
          <cylinder length="0.075" radius="0.111"/>
        </geometry>
      </collision>
    </link>
    <gazebo reference="p3at_front_right_wheel">
      <material value="Gazebo/Black"/>
    </gazebo>
    <joint name="p3at_front_right_wheel_joint" type="continuous">
      <axis xyz="0 1 0"/>
      <anchor xyz="0 0 0"/>
      <limit effort="100" velocity="100"/>
      <joint_properties damping="0.7"/>
      <origin rpy="0 0 0" xyz="0 0 0"/>
      <parent link="p3at_front_right_hub"/>
      <child link="p3at_front_right_wheel"/>
    </joint>
    <!-- Back Axles + Wheels + Hubcaps -->
    <link name="p3at_back_right_axle">
      <inertial>
        <mass value="0.1"/>
        <origin xyz="0 0 0"/>
        <inertia ixx="1.0" ixy="0.0" ixz="0.0" iyy="1.0" iyz="0.0" izz="1.0"/>
      </inertial>
      <visual>
        <origin rpy="0 0 0" xyz="0 0 0"/>
        <geometry name="pioneer_geom">
          <mesh filename="package://follower_description/meshes/p3at/axle.stl"/>
        </geometry>
        <material name="AxleGrey">
          <color rgba="0.5 0.5 0.5 1"/>
        </material>
      </visual>
      <collision>
        <origin rpy="0 0 0" xyz="0 0 0"/>
        <geometry>
          <mesh filename="package://follower_description/meshes/p3at/axle.stl"/>
        </geometry>
      </collision>
    </link>
    <gazebo reference="p3at_back_right_axle">
      <material value="Gazebo/Grey"/>
    </gazebo>
    <joint name="p3at_back_right_axle_joint" type="fixed">
      <origin rpy="0 0 0" xyz="-0.134 -0.156 0.111"/>
      <parent link="base_link"/>
      <child link="p3at_back_right_axle"/>
    </joint>
    <link name="p3at_back_right_hub">
      <inertial>
        <mass value="0.1"/>
        <origin xyz="0 0 0"/>
        <inertia ixx="1.0" ixy="0.0" ixz="0.0" iyy="1.0" iyz="0.0" izz="1.0"/>
      </inertial>
      <visual>
        <origin rpy="0 0 0" xyz="0 0 0"/>
        <geometry name="pioneer_geom">
          <mesh filename="package://follower_description/meshes/p3at/right_hubcap.stl"/>
        </geometry>
        <material name="HubcapYellow"/>
      </visual>
      <collision>
        <origin rpy="0 0 0" xyz="0 0 0"/>
        <geometry>
          <mesh filename="package://follower_description/meshes/p3at/right_hubcap.stl"/>
        </geometry>
      </collision>
    </link>
    <gazebo reference="p3at_back_right_hub">
      <material value="Gazebo/Yellow"/>
    </gazebo>
    <joint name="p3at_back_right_hub_joint" type="fixed">
      <origin rpy="0 0 0" xyz="-0 -0.041 0"/>
      <parent link="p3at_back_right_axle"/>
      <child link="p3at_back_right_hub"/>
    </joint>
    <link name="p3at_back_right_wheel">
      <inertial>
        <mass value="1.2"/>
        <origin xyz="0 0 0"/>
        <inertia ixx="0.012411765597" ixy="0" ixz="0" iyy="0.015218160428" iyz="0" izz="0.011763977943"/>
      </inertial>
      <visual>
        <origin rpy="0 0 0" xyz="0 0 0"/>
        <geometry name="pioneer_geom">
          <mesh filename="package://follower_description/meshes/p3at/wheel.stl"/>
        </geometry>
        <material name="WheelBlack"/>
      </visual>
      <collision>
        <origin rpy="-1.57079635 0 0" xyz="0 0 0"/>
        <geometry>
          <!--mesh filename="package://follower_description/meshes/p3at/wheel.stl"/-->
          <cylinder length="0.075" radius="0.111"/>
        </geometry>
      </collision>
    </link>
    <gazebo reference="p3at_back_right_wheel">
      <material value="Gazebo/Black"/>
    </gazebo>
    <joint name="p3at_back_right_wheel_joint" type="continuous">
      <axis xyz="0 1 0"/>
      <anchor xyz="0 0 0"/>
      <limit effort="100" velocity="100"/>
      <joint_properties damping="0.7"/>
      <origin rpy="0 0 0" xyz="0 0 0"/>
      <parent link="p3at_back_right_hub"/>
      <child link="p3at_back_right_wheel"/>
    </joint>

  <!-- Gazebo -->




  </xacro:macro>
  

</robot>

